Workbook

Sheet Dashboard
A1: FairBanks Community Outreach Program - Promoting Health through Sports
A2: Year 1 Budget Dashboard | Kampala Peri-Urban Pilot | Proposed Start: September 2026
A4: YEAR 1 FUNDING REQUEST | B4: CAMPS / YEAR | C4: BENEFICIARIES REACHED | D4: COST PER BENEFICIARY
A5: ='Annual Summary'!$B$13 -> 50439.8 | B5: =Assumptions!$B$7 -> 12 | C5: =Assumptions!$B$10 -> 4800 | D5: ='Annual Summary'!$B$21 -> 10.508292
A7: Annual Cost by Category (USD)
A8: Category | B8: Annual Amount (USD)
A9: Health Workforce | B9: ='Per-Camp Budget'!G18 -> 7860
A10: Drugs & Medical Supplies | B10: ='Per-Camp Budget'!G24 -> 10560
A11: Sports Massage & Physiotherapy | B11: ='Per-Camp Budget'!G28 -> 720
A12: Hydration & Refreshments | B12: ='Per-Camp Budget'!G34 -> 2550
A13: Ambulance & Emergency Referral | B13: ='Per-Camp Budget'!G37 -> 2160
A14: Venue, Logistics & Equipment | B14: ='Per-Camp Budget'!G46 -> 6660
A15: Community Mobilization | B15: ='Per-Camp Budget'!G52 -> 2760
A16: FCHIP Data & Digital | B16: ='Per-Camp Budget'!G56 -> 480
A17: FCHIP development | B17: 3300
A18: Printing & Registration | B18: ='Per-Camp Budget'!G59 -> 420
A19: Program Management & Overhead | B19: ='Overhead Fixed & Setup'!$E$9 -> 5400
A20: Annual Fixed Costs (Insurance/Compliance) | B20: ='Overhead Fixed & Setup'!$E$18 -> 1250
A21: One-Time Setup & Equipment | B21: ='Overhead Fixed & Setup'!$E$36 -> 6320
A23: All figures are indicative Year-1 planning estimates. See 'Budget Notes & Justification' tab for sources and assumptions.

Sheet Annual Summary
A1: Year 1 Annual Summary - FairBanks Community Outreach Program
A2: Sports & Family Health component | Kampala peri-urban pilot | September/October 2026 - August/September 2027
A4: Budget Line | B4: Amount (USD) | C4: Source
A5: Recurring Camp-Based Program Costs (12 camps/year) | B5: ='Per-Camp Budget'!$G$61 -> 34170 | C5: Per-Camp Budget tab
A6: Program Management & Overhead (Annual) | B6: ='Overhead Fixed & Setup'!$E$9 -> 5400 | C6: Overhead Fixed & Setup tab, Section A
A7: Annual Fixed Costs (Insurance, Compliance, Comms) | B7: ='Overhead Fixed & Setup'!$E$18 -> 1250 | C7: Overhead Fixed & Setup tab, Section B
A8: Subtotal - Recurring Annual Program Costs | B8: =B5+B6+B7 -> 40820 | C8: Sum of rows above
A9: One-Time Setup & Equipment (Year 1 only) | B9: ='Overhead Fixed & Setup'!$E$36 -> 6320 | C9: Overhead Fixed & Setup tab, Section C
A10: Subtotal Before Contingency | B10: =B8+B9 -> 47140 | C10: Recurring + One-Time
A11: Contingency (7%) | B11: =B10*Assumptions!$B$9 -> 3299.8 | C11: Assumptions tab
A13: GRAND TOTAL - YEAR 1 FUNDING REQUEST | B13: =B10+B11 -> 50439.8
A16: KEY METRICS
A17: Camps in Year 1 | B17: =Assumptions!$B$7 -> 12
A18: Average participants per camp | B18: =Assumptions!$B$8 -> 400
A19: Estimated beneficiaries reached (Year 1) | B19: =Assumptions!$B$10 -> 4800
A20: Average program cost per camp (incl. contingency) | B20: =B13/Assumptions!$B$7 -> 4203.3167
A21: Average cost per beneficiary reached | B21: =B13/Assumptions!$B$10 -> 10.508292

Sheet Per-Camp Budget
A1: Per-Camp Budget — Detailed Line Items (USD)
A2: One camp = one outreach day at a church, sports centre or school. Annual = Per-Camp x Camps/Year (Assumptions tab).
A4: Category | B4: Item | C4: Unit | D4: Unit Cost (USD) | E4: Qty / Camp | F4: Line Total / Camp | G4: Annual Total (12 camps)
A5: A. Health Workforce (Camp-Day Facilitation)
B6: Medical Doctor / Physician | C6: day | D6: 70 | E6: 1 | F6: =D6*E6 -> 70 | G6: =F6*Assumptions!$B$7 -> 840
B7: Clinical Officer | C7: day | D7: 45 | E7: 1 | F7: =D7*E7 -> 45 | G7: =F7*Assumptions!$B$7 -> 540
B8: Registered Nurse | C8: day | D8: 30 | E8: 3 | F8: =D8*E8 -> 90 | G8: =F8*Assumptions!$B$7 -> 1080
B9: Physiotherapist / Sports Massage Therapist | C9: day | D9: 35 | E9: 2 | F9: =D9*E9 -> 70 | G9: =F9*Assumptions!$B$7 -> 840
B10: Pharmacist / Dispenser | C10: day | D10: 35 | E10: 1 | F10: =D10*E10 -> 35 | G10: =F10*Assumptions!$B$7 -> 420
B11: Laboratory Technician | C11: day | D11: 35 | E11: 1 | F11: =D11*E11 -> 35 | G11: =F11*Assumptions!$B$7 -> 420
B12: Triage Nurse / Assistant | C12: day | D12: 25 | E12: 2 | F12: =D12*E12 -> 50 | G12: =F12*Assumptions!$B$7 -> 600
B13: Health Educator / Counsellor (HIV testing & counselling, nutrition, family planning) | C13: day | D13: 25 | E13: 2 | F13: =D13*E13 -> 50 | G13: =F13*Assumptions!$B$7 -> 600
B14: FCHIIP Data Clerk / Digital Registration Assistant | C14: day | D14: 20 | E14: 2 | F14: =D14*E14 -> 40 | G14: =F14*Assumptions!$B$7 -> 480
B15: Program Coordinator / Logistics Lead | C15: day | D15: 60 | E15: 1 | F15: =D15*E15 -> 60 | G15: =F15*Assumptions!$B$7 -> 720
B16: Security Guard | C16: day | D16: 15 | E16: 2 | F16: =D16*E16 -> 30 | G16: =F16*Assumptions!$B$7 -> 360
B17: Community Health Worker (CHW/VHT) volunteer stipend | C17: day | D17: 10 | E17: 8 | F17: =D17*E17 -> 80 | G17: =F17*Assumptions!$B$7 -> 960
A18: Subtotal - A. Health Workforce (Camp-Day Facilitation) | F18: =SUM(F6:F17) -> 655 | G18: =SUM(G6:G17) -> 7860
A19: B. Drugs & Medical Supplies
B20: Essential outreach drug kit (analgesics/antipyretics, short-course antibiotics, antimalarials, antihistamines, antacids, dewormers, multivitamins, ORS sachets, family-planning commodities) - see Note 1 | C20: kit | D20: 650 | E20: 1 | F20: =D20*E20 -> 650 | G20: =F20*Assumptions!$B$7 -> 7800
B21: Basic pharmacy & wound-care consumables (gloves, syringes, cotton wool, antiseptic, gauze, bandages, sharps box) | C21: set | D21: 120 | E21: 1 | F21: =D21*E21 -> 120 | G21: =F21*Assumptions!$B$7 -> 1440
B22: Blood glucose test strips & lancets (approx. 150 tests) | C22: pack | D22: 90 | E22: 1 | F22: =D22*E22 -> 90 | G22: =F22*Assumptions!$B$7 -> 1080
B23: BP monitor consumables / batteries | C23: set | D23: 20 | E23: 1 | F23: =D23*E23 -> 20 | G23: =F23*Assumptions!$B$7 -> 240
A24: Subtotal - B. Drugs & Medical Supplies | F24: =SUM(F20:F23) -> 880 | G24: =SUM(G20:G23) -> 10560
A25: C. Sports Massage & Physiotherapy Supplies
B26: Massage oil, lotion & liniment | C26: set | D26: 35 | E26: 1 | F26: =D26*E26 -> 35 | G26: =F26*Assumptions!$B$7 -> 420
B27: Cold spray, kinesiology tape, resistance bands, disposable towels | C27: set | D27: 25 | E27: 1 | F27: =D27*E27 -> 25 | G27: =F27*Assumptions!$B$7 -> 300
A28: Subtotal - C. Sports Massage & Physiotherapy Supplies | F28: =SUM(F26:F27) -> 60 | G28: =SUM(G26:G27) -> 720
A29: D. Hydration & Refreshments
B30: Drinking water (500ml bottles) | C30: bottle | D30: 0.25 | E30: 450 | F30: =D30*E30 -> 112.5 | G30: =F30*Assumptions!$B$7 -> 1350
B31: Oral rehydration / electrolyte drinks | C31: unit | D31: 0.2 | E31: 200 | F31: =D31*E31 -> 40 | G31: =F31*Assumptions!$B$7 -> 480
B32: Juice / glucose drinks (children & elderly) | C32: bottle | D32: 0.3 | E32: 150 | F32: =D32*E32 -> 45 | G32: =F32*Assumptions!$B$7 -> 540
B33: Cups & dispensing supplies | C33: set | D33: 15 | E33: 1 | F33: =D33*E33 -> 15 | G33: =F33*Assumptions!$B$7 -> 180
A34: Subtotal - D. Hydration & Refreshments | F34: =SUM(F30:F33) -> 212.5 | G34: =SUM(G30:G33) -> 2550
A35: E. Ambulance & Emergency Referral
B36: Ambulance standby - vehicle, driver, paramedic & fuel (full day) | C36: day | D36: 180 | E36: 1 | F36: =D36*E36 -> 180 | G36: =F36*Assumptions!$B$7 -> 2160
A37: Subtotal - E. Ambulance & Emergency Referral | F37: =SUM(F36:F36) -> 180 | G37: =SUM(G36:G36) -> 2160
A38: F. Venue, Logistics & Equipment Hire
B39: Canopy / tent hire (large) | C39: unit | D39: 75 | E39: 2 | F39: =D39*E39 -> 150 | G39: =F39*Assumptions!$B$7 -> 1800
B40: Tables & chairs hire | C40: set | D40: 80 | E40: 1 | F40: =D40*E40 -> 80 | G40: =F40*Assumptions!$B$7 -> 960
B41: PA system / sound equipment hire | C41: set | D41: 60 | E41: 1 | F41: =D41*E41 -> 60 | G41: =F41*Assumptions!$B$7 -> 720
...

Sheet Overhead Fixed & Setup
A1: Program Overhead, Annual Fixed Costs & One-Time Setup (USD)
A2: Costs that run year-round or occur once, outside the per-camp-day budget.
A4: SECTION A - Program Management & Overhead (Recurring, Monthly, Year-Round)
A5: Item | B5: Unit | C5: Monthly Cost (USD) | D5: Months/Year | E5: Annual Total
A6: Program Manager (part-time allocation to this program) | B6: month | C6: 200 | D6: =Assumptions!$B$7 -> 12 | E6: =C6*D6 -> 2400
A7: M&E / FCHIIP Systems Officer (part-time) | B7: month | C7: 150 | D7: =Assumptions!$B$7 -> 12 | E7: =C7*D7 -> 1800
A8: Finance & Administration Support (part-time) | B8: month | C8: 100 | D8: =Assumptions!$B$7 -> 12 | E8: =C8*D8 -> 1200
A9: Subtotal - Section A (Program Overhead) | E9: =SUM(E6:E8) -> 5400
A11: SECTION B - Annual Fixed Costs (Insurance, Compliance & Communications)
A12: Item | B12: Unit | C12: Unit Cost (USD) | D12: Qty | E12: Annual Total
A13: Public liability / event insurance | B13: year | C13: 400 | D13: 1 | E13: =C13*D13 -> 400
A14: Staff medical malpractice / first-aid liability cover | B14: year | C14: 300 | D14: 1 | E14: =C14*D14 -> 300
A15: NDA / Ministry of Health regulatory compliance & permits | B15: year | C15: 200 | D15: 1 | E15: =C15*D15 -> 200
A16: Quarterly report design & printing (for funder) | B16: year | C16: 200 | D16: 1 | E16: =C16*D16 -> 200
A17: Website / social media impact updates | B17: year | C17: 150 | D17: 1 | E17: =C17*D17 -> 150
A18: Subtotal - Section B (Annual Fixed Costs) | E18: =SUM(E13:E17) -> 1250
A20: SECTION C - One-Time Setup & Equipment (Year 1 Only)
A21: Item | B21: Unit | C21: Unit Cost (USD) | D21: Qty | E21: Total
A22: Digital blood pressure machines | B22: unit | C22: 60 | D22: 4 | E22: =C22*D22 -> 240
A23: Glucometers + initial test-strip supply | B23: unit | C23: 50 | D23: 4 | E23: =C23*D23 -> 200
A24: Digital thermometers | B24: unit | C24: 15 | D24: 6 | E24: =C24*D24 -> 90
A25: Weighing scales | B25: unit | C25: 40 | D25: 2 | E25: =C25*D25 -> 80
A26: Height measuring boards | B26: unit | C26: 30 | D26: 2 | E26: =C26*D26 -> 60
A27: Folding stretchers / first-aid kits | B27: unit | C27: 80 | D27: 2 | E27: =C27*D27 -> 160
A28: Tablets / smartphones for FCHIIP data capture | B28: unit | C28: 150 | D28: 10 | E28: =C28*D28 -> 1500
A29: Solar power bank / charging station | B29: unit | C29: 60 | D29: 2 | E29: =C29*D29 -> 120
A30: Cold box for vaccines / samples | B30: unit | C30: 70 | D30: 2 | E30: =C30*D30 -> 140
A31: Branded staff & volunteer T-shirts/vests/caps | B31: unit | C31: 8 | D31: 30 | E31: =C31*D31 -> 240
A32: ID badges / lanyards | B32: unit | C32: 3 | D32: 30 | E32: =C32*D32 -> 90
A33: FCHIIP platform outreach-module deployment & customization | B33: one-time | C33: 2000 | D33: 1 | E33: =C33*D33 -> 2000
... A35: Launch event (kickoff with funding partner, community leaders & press) | B35: one-time | C35: 800 | D35: 1 | E35: =C35*D35 -> 800
A36: Subtotal - Section C (One-Time Setup) | E36: =SUM(E22:E35) -> 6320

Sheet Assumptions
A1: Key Planning Assumptions
A2: These drive every formula in this workbook. Change a yellow cell and every total below recalculates.
A4: Assumption | B4: Value | C4: Notes
A5: Program start date | B5: Sep 2026 | C5: Funder indicated September 2026, or October 2026 at the latest.
A6: Pilot geography (Year 1) | B6: Kampala peri-urban | C6: Kyebando-Kisalosalo / Northern Bypass corridor and surrounding peri-urban parishes.
A7: Camps per year | B7: 12 | C7: 1 camp per month, rotating across churches, sports centres and schools.
A8: Average participants per camp | B8: 400 | C8: Midpoint of the 300-500 target range agreed for Year 1.
A9: Contingency rate | B9: 0.07 | C9: Applied to the full Year-1 program cost (7%, standard for a first-year pilot).
A10: Estimated beneficiaries reached (Year 1) | B10: =B7*B8 -> 4800
A12: Cell reference key:
A13: Camps per year | B13: Assumptions!$B$7
A14: Average participants / camp | B14: Assumptions!$B$8
A15: Contingency rate | B15: Assumptions!$B$9
A16: Beneficiaries reached | B16: Assumptions!$B$10

Sheet Budget Notes & Justification
A1: Budget Notes & Justification
A3: Purpose of this workbook
A4: This budget supports the concept note 'FairBanks Community Outreach Program (FairBanks Reach) - Sports & Family Health: A New Component', prepared for a prospective US-based sports-sector funding partner. Sports & Family Health is proposed as a seventh component of the FairBanks Community Outreach Program, alongside its six existing components (Mobile Medical Clinics, Elderly Care Initiative, Health Education, Maternal & Child Health, Free Vaccination Drives, Vision & Dental Care). It covers a Year 1 pilot of 12 monthly camps in Kampala's peri-urban areas, hosted at churches, sports centres and schools. All figures are in US Dollars, presented as planning estimates for the concept/proposal stage.
A6: Legal registration
A7: Prepared on behalf of FairBanks Medical Centre Limited, registered with the Uganda Revenue Authority (TIN 1053370026), principal place of business at Plot 1423 & 1425, Tirupati Road, Kololo, Kampala, Uganda (per Certificate of Registration, Notice DT-1112, dated 02/07/2026).
A9: NOTE 1 - 'Opiate' service line (important compliance clarification)
A10: The original service list included 'opiate' alongside first aid, ambulance, massage, drinks and triage. This budget deliberately does NOT include controlled/narcotic opiate medicines. Distributing narcotics at a community outreach requires a resident prescriber holding a controlled-drugs permit and specific licensing under Uganda's National Drug Authority (NDA) and the Narcotic Drugs and Psychotropic Substances (Control) Act - it is not appropriate or legally permissible in a lay-volunteer/CHW-supported outreach camp. Instead, the Drugs & Medical Supplies line funds standard non-narcotic pain management (paracetamol, ibuprofen/NSAIDs) suitable for sports injuries, headaches and general pain - paired with the physiotherapy/massage service for musculoskeletal complaints. If 'opiate' was intended to mean something else (e.g. IV fluids, oxygen therapy, or a specific emergency drug), please flag it and the line item can be re-costed and added with the correct regulatory pathway.
A12: Health Workforce rates
A13: Day rates are indicative honoraria typical for short-term outreach facilitation of qualified Ugandan health professionals (doctors, clinical officers, nurses, physiotherapists, lab technicians) engaged outside their primary employment, plus CHW/VHT volunteer stipends. Confirm exact rates with FairBanks Medical Centre's HR/clinical team and 2-3 comparator NGOs (e.g. dfcu Bank-Rotary Uganda medical camps, UPDF medical camps) before finalizing with the funder.
A15: Drugs & medical supplies
A16: Priced as a per-camp kit sized for ~400 participants, assuming roughly 30-40% of attendees receive some medication or dressing. Costed from typical Uganda wholesale pharmaceutical/consumables pricing; FairBanks' own pharmacy/procurement team should confirm against current supplier quotes (e.g. Denk Pharma, an existing FairBanks Reach partner) before the budget is finalized.
A18: Ambulance services
... A40: Every yellow cell in this workbook is an editable input (unit costs, quantities, assumptions). Before sharing with the funder, FairBanks' finance/clinical leads should validate at least: health-worker day rates, drug-kit pricing, and ambulance-hire pricing against 2-3 current local quotes, to keep the figures accurate and defensible.

Sheet 3-Year Outlook (Indicative)
A1: 3-Year Geographic Scale-Up Outlook - INDICATIVE, NON-BINDING
A2: High-level planning only. Each phase requires its own detailed budget once Year 1 results and in-country partner assessments are available.
A4: Phase | B4: Geographic Scope | C4: Rough Indicative Budget (USD/yr) | D4: Notes
A5: Year 1 (Pilot) | B5: Kampala peri-urban areas only (Kyebando-Kisalosalo / Northern Bypass corridor) | C5: =ROUND('Annual Summary'!$B$13,0) -> 50440 | D5: The only fully-costed phase - see Annual Summary tab. 12 camps, ~4,800 beneficiaries.
A6: Year 2 (Uganda Scale-Up) | B6: Add 2-3 further Uganda regions (e.g. Wakiso, Mukono, Jinja peri-urban areas); roughly double camp frequency to ~24/year | C6: $95,000 - $115,000 | D6: Indicative only - assumes similar per-camp cost structure with modest efficiency gains, plus added regional coordination staff and transport. To be re-costed using Year 1 actuals.
A7: Year 3 (Regional Pilot) | B7: Pilot partnership in one additional country (e.g. Rwanda or eastern DRC border area), alongside continued Uganda operations | C7: $150,000 - $190,000 | D7: Indicative only - depends heavily on in-country partner identification, import/regulatory requirements for drugs and equipment, and currency/logistics costs, none of which are assessed yet. Not for funder budget commitment purposes.
A8: Future Vision | B8: Full multi-country footprint: Uganda, DRC, Rwanda, Burundi, Tanzania, Malawi | C8: Not costed | D8: Long-term ambition shared for context; formal budgeting begins only after Year 1-2 results are proven.
